Workbook
Name List_No: #REF!
Name List_Yes: #REF!

Sheet Process_Flow

Sheet Q & A
B4: # | C4: Query CIO | D4: Response_MASPL
B5: 1 | C5: Business meaning of TRS, TRF and TL Code; and which of Tool Number or TL Code keys a Tool | D5: TRS - Tool Requirement Sheet, TRF - Tool Request Form, TL code - Unique tool code; Tool number is reference, TL code is generated / Keyed in SAP
B6: 2 | C6: Meaning of MASPL Level, Type, Safety Class, Process — and whether Safety Class alters which milestones apply | D6: MASPL level, type, safety class, process - these are project based inputs does not alter the milestones
B7: 3 | C7: Exact column split between Configuration and Engineering (proposal in §5) | D7: We discussed, Configuration takes input from Engineering and creates WO number for each part number
B8: 4 | C8: Whether Engineering's tool columns are dropped and read through from Tooling (proposal in §5) | D8: Yes, part number wise complete data set is pulled in from tooling tracker, need to check on commonlising / automate to unite
B9: 5 | C9: Stage closure: self-closure by the owning role in Phase 1, with RFA multi-level approval in Phase 2? | D9: To be discussed
B10: 6 | C10: Bid lifecycle — retention of lost and expired bids, superseding vs retaining rounds | D10: Discussed
B11: 7 | C11: Who may view RC / NRC / NRC OT prices. The BRD role matrix is silent, which currently exposes pricing to every role | D11: currently this is manual input and saved in SAP
B12: 8 | C12: Tool KPI counting under many-to-many — distinct Tools vs Tool Applications | D12: discussed, tool number and part number are many to many relation
B13: 9 | C13: Ingestion failure handling — field-level quarantine vs row rejection | D13: To be discussed
B14: 10 | C14: Audit identity and source value for machine writes | D14: To be discussed
B15: 11 | C15: Whether field ownership is fixed in code or admin-configurable | D15: admin - configurable
B16: 12 | C16: Terminal events closing the Tooling and SCM tracks, and whether a part may reach Quality with Tooling open | D16: Final Quality will receive once all the previous gates are closed
... B21: 17 | C21: Expected data volume and concurrency for sizing | D21: DATA Volume - we had discussed, currently we are seeing around 10,000 unique part numbers, but the rate at which MASPL is growing we can easily reach around 40 - 50K including continuous deliverables (historic data), live data can be around 20 - 25 K on higher side

Sheet INPUT_BD
B2: SAP | C2: SAP | E2: SAP | F2: SAP | G2: SUPPLIER PORTAL / EMAIL | H2: SUPPLIER PORTAL / EMAIL | I2: MANUAL | J2: MANUAL | K2: FORMULA | L2: FORMULA | N2: SAP | O2: SAP | P2: Manual
A4: Doc_type | B4: Doc_No | C4: Doc_Date | D4: sl_no | E4: Version no | F4: Customer_code | G4: Project_Name | H4: Customer_material_code | I4: Price_Currency | J4: RC Price (Basic Price) | K4: NRC Price (Amortisation Price) | L4: NRC Amortised QTY | M4: NRC_OT Price | N4: Bid- Valid_From_date | O4: Bid -Valid_To_date | P4: Planned Submission Date
A5: BID | B5: MASPL-RFQ-ABS-301-2024 | C5: 29.04.2025 | D5: 1 | E5: Round 1 | F5: MSAXYZ0005 | G5: ABS | H5: Z579-13034-304-00 | I5: USD | J5: 1.11 | M5: 15 | N5: 29.04.2025 | O5: 31.12.2030 | P5: 45555
A6: BID | B6: MASPL-RFQ-ABS-301-2024 | C6: 29.04.2025 | D6: 2 | E6: Round 1 | F6: MSAXYZ0005 | G6: ABS | H6: Z579-13033-304-00 | I6: USD | J6: 1.12 | M6: 15 | N6: 29.04.2025 | O6: 31.12.2030 | P6: 45555
A7: BID | B7: MASPL-RFQ-ABS-301-2024 | C7: 29.04.2025 | D7: 3 | E7: Round 1 | F7: MSAXYZ0005 | G7: ABS | H7: Z579-13037-304-00 | I7: USD | J7: 1.13 | M7: 15 | N7: 29.04.2025 | O7: 31.12.2030 | P7: 45555
A8: BID | B8: MASPL-RFQ-ABS-301-2024 | C8: 29.04.2025 | D8: 4 | E8: Round 1 | F8: MSAXYZ0005 | G8: ABS | H8: Z579-13035-304-00 | I8: USD | J8: 1.14 | M8: 15 | N8: 29.04.2025 | O8: 31.12.2030 | P8: 45555
A9: BID | B9: MASPL-RFQ-ABS-301-2024 | C9: 29.04.2025 | D9: 5 | E9: Round 1 | F9: MSAXYZ0005 | G9: ABS | H9: Z579-13197-303-00 | I9: USD | J9: 1.15 | M9: 15 | N9: 29.04.2025 | O9: 31.12.2030 | P9: 45555
A10: BID | B10: MASPL-RFQ-ABS-301-2024 | C10: 29.04.2025 | D10: 6 | E10: Round 1 | F10: MSAXYZ0005 | G10: ABS | H10: Z579-13031-304-00 | I10: USD | J10: 1.16 | M10: 15 | N10: 29.04.2025 | O10: 31.12.2030 | P10: 45555
A11: BID | B11: MASPL-RFQ-ABS-301-2024 | C11: 29.04.2025 | D11: 7 | E11: Round 1 | F11: MSAXYZ0005 | G11: ABS | H11: Z539-10640-000-00 | I11: USD | J11: 1.17 | M11: 15 | N11: 29.04.2025 | O11: 31.12.2030 | P11: 45555
A12: BID | B12: MASPL-RFQ-ABS-301-2024 | C12: 29.04.2025 | D12: 8 | E12: Round 1 | F12: MSAXYZ0005 | G12: ABS | H12: X539-36801-303-00 | I12: USD | J12: 1.18 | M12: 15 | N12: 29.04.2025 | O12: 31.12.2030 | P12: 45555
A13: BID | B13: MASPL-RFQ-ABS-301-2024 | C13: 29.04.2025 | D13: 9 | E13: Round 1 | F13: MSAXYZ0005 | G13: ABS | H13: Z539-10678-300-00 | I13: USD | J13: 1.19 | M13: 15 | N13: 29.04.2025 | O13: 31.12.2030 | P13: 45555
A14: BID | B14: MASPL-RFQ-ABS-301-2024 | C14: 29.04.2025 | D14: 10 | E14: Round 1 | F14: MSAXYZ0005 | G14: ABS | H14: Z539-36801-304-00 | I14: USD | J14: 1.2 | M14: 25 | N14: 29.04.2025 | O14: 31.12.2030 | P14: 45555
A15: BID | B15: MASPL-RFQ-ABS-301-2024 | C15: 29.04.2025 | D15: 11 | E15: Round 1 | F15: MSAXYZ0005 | G15: ABS | H15: Z539-36801-306-00 | I15: USD | J15: 1.21 | M15: 40 | N15: 29.04.2025 | O15: 31.12.2030 | P15: 45555

Sheet Programs
C1: SUPPLIER PORTAL / EMAIL | D1: SUPPLIER PORTAL / EMAIL | E1: Manual | H1: SUPPLIER PORTAL / EMAIL | I1: CALCULATION | J1: SAP | K1: SUPPLIER PORTAL / EMAIL | L1: SAP / QUALITY TRACKER | M1: Maunal
B2: Manual | C2: BD | D2: BD | E2: Manual | F2: Manual | G2: Manual | H2: Manual
C3: Column -1 | D3: Column -2 | I3: Column - 4 = Column 3 - 64 days | K3: Column - 3
A4: Sr. No. | B4: Customer | C4: Project | D4: Material Number | E4: PART DESCRIPTION | F4: Sub project name | G4: TYPE | H4: Order Type | I4: Planned Launch Date | J4: Actual Release Date | K4: Planned Submission Date | L4: Actual Submission Date | M4: Annual Demand
A5: 1 | B5: ATLANTIC | C5: ABS | D5: Z5791303430400 | E5: ANGLE | F5: W1 | G5: DETAIL PART | H5: FAI | I5: 45491 | J5: 45463 | K5: 45555 | L5: 45561
A6: 2 | B6: ATLANTIC | C6: ABS | D6: Z5791303330400 | E6: SHIM | F6: W1 | G6: DETAIL PART | H6: FAI | I6: 45491 | J6: 45463 | K6: 45555 | L6: 45560
A7: 3 | B7: ATLANTIC | C7: ABS | D7: Z5791303730400 | E7: SEN ELEMENT BRACKET | F7: W1 | G7: EQP ASSEMBLY. | H7: FAI | I7: 45491 | J7: 45463 | K7: 45555 | L7: 45561
A8: 4 | B8: ATLANTIC | C8: ABS | D8: Z5791303530400 | E8: CLAMP RING | F8: W1 | G8: DETAIL PART | H8: FAI | I8: 45491 | J8: 45463 | K8: 45555 | L8: 45555
A9: 5 | B9: ATLANTIC | C9: ABS | D9: Z5791319730300 | E9: ACT-PROTECTION GRID | F9: W1 | G9: DETAIL PART | H9: FAI | I9: 45491 | J9: 45505 | K9: 45555 | L9: 45559
A10: 6 | B10: ATLANTIC | C10: ABS | D10: Z5791303130400 | E10: SUPPORT | F10: W1 | G10: DETAIL PART | H10: FAI | I10: 45491 | J10: 45463 | K10: 45555 | L10: 45561
A11: 7 | B11: ATLANTIC | C11: ABS | D11: Z5391064000000 | E11: ANGLE | F11: W1 | G11: DETAIL PART | H11: FAI | I11: 45491 | J11: 45464 | K11: 45555 | L11: 45559
A12: 8 | B12: ATLANTIC | C12: ABS | D12: X5393680130300 | E12: BRACKET | F12: W1 | G12: DETAIL PART | H12: FAI | I12: 45491 | J12: 45463 | K12: 45555 | L12: 45560
A13: 9 | B13: ATLANTIC | C13: ABS | D13: Z5391067830000 | E13: BRACKET F ELECTRIC | F13: W1 | G13: ASSEMBLY | H13: FAI | I13: 45491 | J13: 45464 | K13: 45555 | L13: 45554
A14: 10 | B14: ATLANTIC | C14: ABS | D14: Z5393680130400 | E14: BRACKET F.ELECTRIC | F14: W1 | G14: DETAIL PART | H14: FAI | I14: 45491 | J14: 45505 | K14: 45555 | L14: 45560
A15: 11 | B15: ATLANTIC | C15: ABS | D15: Z5393680130600 | E15: ANGLE | F15: W1 | G15: DETAIL PART | H15: FAI | I15: 45491 | J15: 45505 | K15: 45555 | L15: 45560
H20: Dropdown value
H21: FAI / DFAI

Sheet Engineering
D2: From SAP | M2: TDP available or not if available then only insert date | N2: TDP available or not if available then only insert date | AI2: Formula if this part is available in tooling then yes otherwise No | BM2: if inhouse filled by enginnering if outsource then data coming from SCM
L3: col 13 = col8 - 180 days | O3: col 12 = col8 - 150 days | Y3: Engineering | Z3: Engineering | AC3: col 12 = col8 -120 | AL3: col 11 = col 8 - 21 days | AY3: col 10 = col 7 - 21 days | BD3: col 9 = col 8 - 7 days | BH3: col 8 = col 7 - 4 | BQ3: col 7 = col 6- 15 days | BR3: SAP | BS3: col 6 = col 5 - 7 days | BT3: SAP | BU3: col 5 = col 4 - 15days | BV3: SAP | BW3: col 4 = col 3 - 7 days | BX3: SAP | BY3: col3 =col2 -10 days | BZ3: SAP | CA3: col2 =col1 -3 days | CB3: Eng | CD3: SAP | CE3: SAP | CF3: SAP | CG3: Eng | CH3: Refer - Input Programs - Column 4 COLUMN 1 | CI3: SAP | CJ3: SAP | CK3: SAP | CL3: SAP | CM3: Eng
C4: manual entery by Eng | D4: BD / Programs | E4: just add - in MASPL | F4: BD / Programs | G4: BD / Programs | H4: BD / Programs | I4: BD / Programs | J4: Engineering | K4: Engineering | M4: Engineering | N4: Engineering | P4: Engineering | Q4: Engineering | R4: Engineering | S4: Engineering | T4: Engineering | U4: Engineering | V4: Engineering | W4: Engineering | X4: Engineering | Y4: YES/NO | Z4: APPROVED/ME WIP/CUST.WIP | AA4: Engineering | AB4: Engineering | AD4: Engineering | AE4: Engineering | AF4: Engineering | AG4: Engineering | AH4: Engineering | AI4: Engineering | AJ4: if tool is available then coming from Tooling | AV4: Engineering | AW4: Engineering | AX4: Engineering | AZ4: Engineering | BA4: Engineering | BB4: Engineering | BC4: Engineering | BE4: Engineering | BF4: SAP | BG4: SAP | BH4: Configuration | BI4: Engineering | BJ4: Configuration | BK4: Engineering | BL4: Engineering | BM4: Engineering | BN4: Engineering | BO4: Engineering | BP4: Engineering | BQ4: 7 | BS4: 15 | BU4: 7 | BW4: 15 | BY4: 7
L5: TDP | O5: FEASIBILITY STUDY | R5: BOM CREATION | U5: CUSTOMER APPROVAL | AC5: CONCURRENCE | AF5: TOOL APPROVAL | AI5: TOOLS | AV5: RAW MATERIAL & BOI | BC5: NC PROGRAM STATUS | BF5: FAI LAUNCH STSTUS | BQ5: ISSUE OF RM | BS5: COMP | BU5: PART CONFIG (FORMING +HT+M/C) | BW5: SST | BY5: ASSY | CA5: FINAL INSPECTION | CG5: FAI SUBMISSION
B6: Sl.No | C6: MASPL LEVEL | D6: MASPL PN (AS PER SAP) | E6: CUSTOMER PN | F6: PART DESCRIPTION | G6: Project | H6: Sub project name | I6: TYPE | J6: SAFETY CLASS | K6: PROCESS | L6: TDP PLAN DATE | M6: TDP ACTUAL DATE | N6: TDP AVAILABILITY | O6: FEASIBILITY PLAN DATE | P6: FEASIBILITY ACTUAL DATE | Q6: FEASIBILTY STUDY | R6: RM BOM STATUS | S6: CONSUMABLE BOM STATUS | T6: HW BOM STATUS | U6: SST PROCESS QUALIFICATION REQUIREMENTS | V6: SST PROCESS NEEDED QULIFICATION | W6: SST PROCESS QUALIFICATION STATUS | X6: LAI APPROVAL | Y6: FPQ APPROVAL REQUIREMENTS | Z6: FPQ APPROVAL STATUS | AA6: ME EDC | AB6: CUST. EDC | AC6: CONCURRENCE PLAN DATE | AD6: CONCURRENCE ACTUAL DATE | AE6: CONCURRENCE STATUS | AF6: TOOL CONCEPT REQUIREMENTS | AG6: TOOL CONCEPT APPROVAL STATUS | AH6: TOOL DESIGN APPROVAL | AI6: TOOLS NEEDED? | AJ6: TOOL TYPE | AK6: NO OF TOOLS | AL6: TOOL PLAN DATE | AM6: COMMITTED DATE | AN6: TOOL ACTUAL DATE | AO6: TOOL AVAILIABILITY | AP6: TRF HANDOVER | AQ6: TOOL DESIGN | AR6: TOOL FABRICATION | AS6: TOOL NUMBER | AT6: TL CODE | AU6: DEPENDENCY | AV6: FINAL TEMP | AW6: THICKNESS | AX6: RM/BOI Num (as per SAP) | AY6: RM NEED DATE | AZ6: BOI NEED DATE | BA6: RM STATUS | BB6: BOI STATUS | BC6: NC PROGRAM TYPE | BD6: NC PROGRAM COMPLETION PLAN DATE | BE6: NC PROGRAM COMPLETION ACTUAL DATE | BF6: W/O - SAP | BG6: W/O Date - SAP | BH6: WO PLAN RELEASE DATE | BI6: DELINQUENCY | BJ6: LAUNCH STATUS | BK6: LC DEPENDENCY | BL6: LC DEPENDENCY BREAKUP | BM6: DOSSIAR INHOUSE/OUTSOURCE | BN6: PRIORITY | BO6: TQ REQUIRED | BP6: TQ RAISED | BQ6: PLAN DATE | BR6: ACTUAL DATE | BS6: PLAN DATE | BT6: ACTUAL DATE | BU6: PLAN DATE | BV6: ACTUAL DATE | BW6: PLAN DATE | BX6: ACTUAL DATE | BY6: PLAN DATE | BZ6: ACTUAL DATE | CA6: PLAN DATE | CB6: Revised Plan | CD6: Comp. FI & SST | CE6: Comp. FI & LC | CF6: ACTUAL DATE | CG6: REVIEW | CH6: FAI SUBMISSION PLAN DATE | CI6: FAI SUBMISSION ACTUAL DATE | CJ6: DELAY | CK6: FAI SUBMISSION DEPENDENCY | CL6: FAI SUBMISSION DEPENDENCY BREAKUP | CM6: Remarks
B7: 13 | D7: Z5791303430400 | E7: Z579-13034-304-00 | F7: ANGLE | G7: ABS | H7: W1 | I7: DETAIL PART | K7: ROUTING+PB | L7: =BH7-180 -> 45212 | M7: 45212 | N7: TDP AVAILABLE | O7: =BH7-150 -> 45242 | P7: 45242 | Q7: FEASIBILITY STUDY COMPLETED | R7: COMPLETED | S7: COMPLETED | T7: COMPLETED | U7: NO | V7: NA | W7: NA | AC7: =BH7-120 -> 45272 | AD7: 45272 | AE7: CONCURRENCE COMPLETED | AI7: NO | AJ7: NA | AK7: NA | AL7: NA | AM7: NA | AN7: NA | AO7: NA | AQ7: NA | AR7: NA | AU7: NA | AV7: T351 | AW7: 1.2 | AY7: =BQ7-21 -> 45375 | BD7: =BH7-5 -> 45387 | BF7: 21002672 | BG7: 45362 | BH7: =BQ7-4 -> 45392 | BJ7: LAUNCHED | BK7: NA | BL7: NA | BM7: NA | BN7: NA | BO7: NO | BP7: NO | BQ7: 45396 | BR7: 45386 | BS7: =BQ7+5 -> 45401 | BU7: =BS7+4 -> 45405 | BW7: =BU7+15 -> 45420 | CA7: =CH7-3 -> 45552 | CH7: 45555 | CI7: 45561 | CL7: FAI SUBMITTED
B8: 14 | D8: Z5791303330400 | E8: Z579-13033-304-00 | F8: SHIM | G8: ABS | H8: W1 | I8: DETAIL PART | K8: ROUTING | L8: =BH8-180 -> 45212 | M8: 45212 | N8: TDP AVAILABLE | O8: =BH8-150 -> 45242 | P8: 45242 | Q8: FEASIBILITY STUDY COMPLETED | R8: COMPLETED | S8: COMPLETED | T8: COMPLETED | U8: NO | V8: NA | W8: NA | AC8: =BH8-120 -> 45272 | AD8: 45272 | AE8: CONCURRENCE COMPLETED | AI8: NO | AJ8: NA | AK8: NA | AL8: NA | AM8: NA | AN8: NA | AO8: NA | AQ8: NA | AR8: NA | AU8: NA | AV8: T351 | AW8: 1.2 | AY8: =BQ8-21 -> 45375 | BD8: =BH8-5 -> 45387 | BF8: 21002756 | BG8: 45366 | BH8: =BQ8-4 -> 45392 | BJ8: LAUNCHED | BK8: NA | BL8: NA | BM8: NA | BN8: NA | BO8: NO | BP8: NO | BQ8: 45396 | BR8: 45386 | BS8: =BQ8+5 -> 45401 | BU8: =BS8+4 -> 45405 | BW8: =BU8+15 -> 45420 | CA8: =CH8-3 -> 45552 | CH8: 45555 | CI8: 45560 | CL8: FAI SUBMITTED
B9: 15 | D9: Z5791303730400 | E9: Z579-13037-304-00 | F9: SEN ELEMENT BRACKET | G9: ABS | H9: W1 | I9: EQP ASSEMBLY. | L9: =BH9-180 -> 45771 | M9: 45771 | N9: TDP AVAILABLE | O9: =BH9-150 -> 45801 | P9: 45801 | Q9: FEASIBILITY STUDY COMPLETED | R9: COMPLETED | S9: COMPLETED | T9: COMPLETED | U9: NO | V9: NA | W9: NA | AC9: =BH9-120 -> 45831 | AD9: 45831 | AE9: CONCURRENCE COMPLETED | AI9: NO | AJ9: NA | AK9: NA | AL9: NA | AM9: NA | AN9: NA | AO9: NA | AQ9: NA | AR9: NA | AU9: NA | AV9: 1.4544.9 | AW9: 0.6 | AY9: =BQ9-21 -> 45934 | BD9: =BH9-5 -> 45946 | BF9: 21014016 | BG9: 45979 | BH9: =BQ9-4 -> 45951 | BJ9: LAUNCHED | BK9: NA | BL9: NA | BM9: NA | BN9: NA | BO9: NO | BP9: NO | BQ9: 45955 | BR9: 45955 | BS9: =BQ9+5 -> 45960 | BU9: =BS9+4 -> 45964 | BW9: =BU9+15 -> 45979 | CA9: =CH9-3 -> 45552 | CH9: 45555 | CI9: 45561 | CL9: FAI SUBMITTED
B10: 16 | D10: Z5791303530400 | E10: Z579-13035-304-00 | F10: CLAMP RING | G10: ABS | H10: W1 | I10: DETAIL PART | K10: LASER+HEZ+PRESS | L10: =BH10-180 -> 45679 | M10: 45679 | N10: TDP AVAILABLE | O10: =BH10-150 -> 45709 | P10: 45709 | Q10: FEASIBILITY STUDY COMPLETED | R10: COMPLETED | S10: COMPLETED | T10: COMPLETED | U10: NO | V10: NA | W10: NA | AC10: =BH10-120 -> 45739 | AD10: 45739 | AE10: CONCURRENCE COMPLETED | AI10: YES | AJ10: PRESS TOOL | AN10: 45474 | AO10: YES | AP10: YES | AQ10: COMPLETED | AR10: COMPLETED | AT10: TL0340080010003 | AU10: NA | AV10: 1.4544.9 | AW10: 2 | AY10: =BQ10-21 -> 45842 | BD10: =BH10-5 -> 45854 | BF10: 21011803 | BG10: 45856 | BH10: =BQ10-4 -> 45859 | BJ10: LAUNCHED | BK10: NA | BL10: NA | BM10: NA | BN10: NA | BO10: NO | BP10: NO | BQ10: 45863 | BR10: 45863 | BS10: =BQ10+5 -> 45868 | BU10: =BS10+4 -> 45872 | BW10: =BU10+15 -> 45887 | CA10: =CH10-3 -> 45552 | CH10: 45555 | CI10: 45555 | CL10: FAI SUBMITTED
B11: 17 | D11: Z5791319730300 | E11: Z579-13197-303-00 | F11: ACT-PROTECTION GRID | G11: ABS | H11: W1 | I11: DETAIL PART | K11: ROUTING+PB | L11: =BH11-180 -> 45309 | M11: 45309 | N11: TDP AVAILABLE | O11: =BH11-150 -> 45339 | P11: 45339 | Q11: FEASIBILITY STUDY COMPLETED | R11: COMPLETED | S11: COMPLETED | T11: COMPLETED | U11: NO | V11: NA | W11: NA | AC11: =BH11-120 -> 45369 | AD11: 45369 | AE11: CONCURRENCE COMPLETED | AI11: NO | AJ11: NA | AK11: NA | AL11: NA | AM11: NA | AN11: NA | AO11: NA | AQ11: NA | AR11: NA | AU11: NA | AV11: T42 | AW11: 1.2 | AY11: =BQ11-21 -> 45472 | BD11: =BH11-5 -> 45484 | BF11: 21005043 | BG11: 45491 | BH11: =BQ11-4 -> 45489 | BJ11: LAUNCHED | BK11: NA | BL11: NA | BM11: NA | BN11: NA | BO11: NO | BP11: NO | BQ11: 45493 | BR11: 45491 | BS11: =BQ11+5 -> 45498 | BU11: =BS11+4 -> 45502 | BW11: =BU11+15 -> 45517 | CA11: =CH11-3 -> 45552 | CH11: 45555 | CI11: 45559 | CL11: FAI SUBMITTED
B12: 18 | D12: Z5791303130400 | E12: Z579-13031-304-00 | F12: SUPPORT | G12: ABS | H12: W1 | I12: DETAIL PART | K12: ROUTING+PB | L12: =BH12-180 -> 45207 | M12: 45207 | N12: TDP AVAILABLE | O12: =BH12-150 -> 45237 | P12: 45237 | Q12: FEASIBILITY STUDY COMPLETED | R12: COMPLETED | S12: COMPLETED | T12: COMPLETED | U12: NO | V12: NA | W12: NA | AC12: =BH12-120 -> 45267 | AD12: 45267 | AE12: CONCURRENCE COMPLETED | AI12: NO | AJ12: NA | AK12: NA | AL12: NA | AM12: NA | AN12: NA | AO12: NA | AQ12: NA | AR12: NA | AU12: NA | AV12: T42 | AW12: 1.6 | AY12: =BQ12-21 -> 45370 | BD12: =BH12-5 -> 45382 | BF12: 21003087 | BG12: 45387 | BH12: =BQ12-4 -> 45387 | BJ12: LAUNCHED | BK12: NA | BL12: NA | BM12: NA | BN12: NA | BO12: NO | BP12: NO | BQ12: 45391 | BR12: 45386 | BS12: =BQ12+5 -> 45396 | BU12: =BS12+4 -> 45400 | BW12: =BU12+15 -> 45415 | CA12: =CH12-3 -> 45552 | CH12: 45555 | CI12: 45561 | CL12: FAI SUBMITTED
B13: 19 | D13: Z5391064000000 | E13: Z539-10640-000-00 | F13: ANGLE | G13: ABS | H13: W1 | I13: DETAIL PART | K13: ROUTING+PB | L13: =BH13-180 -> 45528 | M13: 45528 | N13: TDP AVAILABLE | O13: =BH13-150 -> 45558 | P13: 45558 | Q13: FEASIBILITY STUDY COMPLETED | R13: COMPLETED | S13: COMPLETED | T13: COMPLETED | U13: NO | V13: NA | W13: NA | AC13: =BH13-120 -> 45588 | AD13: 45588 | AE13: CONCURRENCE COMPLETED | AI13: NO | AJ13: NA | AK13: NA | AL13: NA | AM13: NA | AN13: NA | AO13: NA | AQ13: NA | AR13: NA | AU13: NA | AV13: T42 | AW13: 1.6 | AY13: =BQ13-21 -> 45691 | BD13: =BH13-5 -> 45703 | BF13: 21007077 | BG13: 45695 | BH13: =BQ13-4 -> 45708 | BJ13: LAUNCHED | BK13: NA | BL13: NA | BM13: NA | BN13: NA | BO13: NO | BP13: NO | BQ13: 45712 | BR13: 45712 | BS13: =BQ13+5 -> 45717 | BU13: =BS13+4 -> 45721 | BW13: =BU13+15 -> 45736 | CA13: =CH13-3 -> 45552 | CH13: 45555 | CI13: 45559 | CL13: FAI SUBMITTED
B14: 20 | D14: X5393680130300 | E14: X539-36801-303-00 | F14: BRACKET | G14: ABS | H14: W1 | I14: DETAIL PART | K14: ROUTING+PB+HF | L14: =BH14-180 -> 45576 | M14: 45576 | N14: TDP AVAILABLE | O14: =BH14-150 -> 45606 | P14: 45606 | Q14: FEASIBILITY STUDY COMPLETED | R14: COMPLETED | S14: COMPLETED | T14: COMPLETED | U14: NO | V14: NA | W14: NA | AC14: =BH14-120 -> 45636 | AD14: 45636 | AE14: CONCURRENCE COMPLETED | AI14: YES | AJ14: HAND FORMING TOOL | AO14: YES | AP14: YES | AQ14: COMPLETED | AR14: COMPLETED | AU14: NA | AV14: T42 | AW14: 1.2 | AY14: =BQ14-21 -> 45739 | BD14: =BH14-5 -> 45751 | BF14: 21009445 | BG14: 45740 | BH14: =BQ14-4 -> 45756 | BJ14: LAUNCHED | BK14: NA | BL14: NA | BM14: NA | BN14: NA | BO14: NO | BP14: NO | BQ14: 45760 | BR14: 45760 | BS14: =BQ14+5 -> 45765 | BU14: =BS14+4 -> 45769 | BW14: =BU14+15 -> 45784 | CA14: =CH14-3 -> 45552 | CH14: 45555 | CI14: 45560 | CL14: FAI SUBMITTED
B15: 21 | D15: Z5391067830000 | E15: Z539-10678-300-00 | F15: BRACKET F ELECTRIC | G15: ABS | H15: W1 | I15: ASSEMBLY | L15: =BH15-180 -> 45243 | M15: 45243 | N15: TDP AVAILABLE | O15: =BH15-150 -> 45273 | P15: 45273 | Q15: FEASIBILITY STUDY COMPLETED | R15: COMPLETED | S15: COMPLETED | T15: COMPLETED | U15: NO | V15: NA | W15: NA | AC15: =BH15-120 -> 45303 | AD15: 45303 | AE15: CONCURRENCE COMPLETED | AI15: NO | AJ15: NA | AK15: NA | AL15: NA | AM15: NA | AN15: NA | AO15: NA | AQ15: NA | AR15: NA | AU15: NA | AV15: T351 | AW15: 1 | AY15: =BQ15-21 -> 45406 | BD15: =BH15-5 -> 45418 | BF15: 21003861 | BG15: 45427 | BH15: =BQ15-4 -> 45423 | BJ15: LAUNCHED | BK15: NA | BL15: NA | BM15: NA | BN15: NA | BO15: NO | BP15: NO | BQ15: 45427 | BR15: 45422 | BS15: =BQ15+5 -> 45432 | BU15: =BS15+4 -> 45436 | BW15: =BU15+15 -> 45451 | CA15: =CH15-3 -> 45552 | CH15: 45555 | CI15: 45554 | CL15: FAI SUBMITTED
B16: 22 | D16: Z5393680130400 | E16: Z539-36801-304-00 | F16: BRACKET F.ELECTRIC | G16: ABS | H16: W1 | I16: DETAIL PART | K16: ROUTING+PB | L16: =BH16-180 -> 45108 | M16: 45108 | N16: TDP AVAILABLE | O16: =BH16-150 -> 45138 | P16: 45138 | Q16: FEASIBILITY STUDY COMPLETED | R16: COMPLETED | S16: COMPLETED | T16: COMPLETED | U16: NO | V16: NA | W16: NA | AC16: =BH16-120 -> 45168 | AD16: 45168 | AE16: CONCURRENCE COMPLETED | AI16: NO | AJ16: NA | AK16: NA | AL16: NA | AM16: NA | AN16: NA | AO16: NA | AQ16: NA | AR16: NA | AU16: NA | AV16: T42 | AW16: 1.2 | AY16: =BQ16-21 -> 45271 | BD16: =BH16-5 -> 45283 | BF16: 21001863 | BG16: 45316 | BH16: =BQ16-4 -> 45288 | BJ16: LAUNCHED | BK16: NA | BL16: NA | BM16: NA | BN16: NA | BO16: NO | BP16: NO | BQ16: 45292 | BR16: 45287 | BS16: =BQ16+5 -> 45297 | BU16: =BS16+4 -> 45301 | BW16: =BU16+15 -> 45316 | CA16: =CH16-3 -> 45552 | CH16: 45555 | CI16: 45560 | CL16: FAI SUBMITTED
B17: 23 | D17: Z5393680130600 | E17: Z539-36801-306-00 | F17: ANGLE | G17: ABS | H17: W1 | I17: DETAIL PART | K17: ROUTING+CHAMFER+PB | L17: =BH17-180 -> 45177 | M17: 45177 | N17: TDP AVAILABLE | O17: =BH17-150 -> 45207 | P17: 45207 | Q17: FEASIBILITY STUDY COMPLETED | R17: COMPLETED | S17: COMPLETED | T17: COMPLETED | U17: NO | V17: NA | W17: NA | AC17: =BH17-120 -> 45237 | AD17: 45237 | AE17: CONCURRENCE COMPLETED | AI17: NO | AJ17: NA | AK17: NA | AL17: NA | AM17: NA | AN17: NA | AO17: NA | AQ17: NA | AR17: NA | AU17: NA | AV17: T762 | AW17: 2.5 | AY17: =BQ17-21 -> 45340 | BD17: =BH17-5 -> 45352 | BF17: 21003799 | BG17: 45427 | BH17: =BQ17-4 -> 45357 | BJ17: LAUNCHED | BK17: NA | BL17: NA | BM17: NA | BN17: NA | BO17: NO | BP17: NO | BQ17: 45361 | BR17: 45361 | BS17: =BQ17+5 -> 45366 | BU17: =BS17+4 -> 45370 | BW17: =BU17+15 -> 45385 | CA17: =CH17-3 -> 45552 | CH17: 45555 | CI17: 45560 | CL17: FAI SUBMITTED

Sheet Tooling
B3: MASTER TRACKER | C3: MASTER TRACKER | D3: MASTER TRACKER | E3: MANUAL | F3: FORMULA / MASTER TRACKER | G3: BD / PROGRAMS | H3: MASTER TRACKER | I3: FORMULA | J3: MANUAL | K3: MANUAL | L3: FORMULA | M3: MANUAL | N3: MANUAL | O3: TOOLING SUB - TRACKER | P3: MANUAL | Q3: MANUAL | R3: MANUAL | S3: MANUAL | T3: MANUAL | U3: FORMULA | V3: MANUAL | W3: MANUAL | X3: MANUAL | Y3: FROM SCM TRACKER | Z3: FROM SCM TRACKER | AA3: FROM SCM TRACKER | AB3: FORMULA | AC3: FORMULA | AD3: MANUAL | AE3: MANUAL | AF3: MANUAL | AG3: MANUAL | AH3: MANUAL | AI3: MANUAL | AJ3: MANUAL | AK3: DROP DOWN | AL3: FORMULA | AM3: MANUAL | AN3: MANUAL | AO3: MANUAL | AP3: MANUAL | AQ3: TOOLING SUB TRACKER | AR3: DROP DOWN | AS3: MANUAL | AT3: FORMULA | AU3: MANUAL | AV3: MANUAL | AW3: MANUAL | AX3: FROM SCM TRACKER | AY3: FROM SCM TRACKER | AZ3: FROM SCM TRACKER | BA3: FORMULA | BB3: FORMULA | BC3: FROM SCM TRACKER | BD3: FROM SCM TRACKER | BE3: MANUAL | BF3: FORMULA | BG3: MANUAL | BH3: MANUAL | BI3: MANUAL | BJ3: MANUAL | BK3: MANUAL | BL3: MANUAL | BM3: MANUAL | BN3: MANUAL | BO3: MANUAL | BP3: MANUAL | BQ3: MANUAL | BR3: FORMULA | BS3: MANUAL
H4: Column 1 = column 4 from Programs | I4: column 2 = column 1 -21 | L4: col 8 = col 7 - 22 | AB4: col 7 = col 6 -60 | AC4: col 6= col5 -15 | AT4: col 5 = col 4 - 7 | BA4: Col 4 = col 3 - 90 | BB4: Column 3 = col 2 -21 days
J6: GATE-1 | T6: SCM | AF6: CustomerApproval | AI6: GATE-2 | AS6: SCM | BH6: YES / NO | BI6: GATE-3 | BK6: GATE-4
A7: SL.No | B7: Customer | C7: Project | D7: Derivable Part No | E7: Part No | F7: SAP No | G7: Annual Demand | H7: Part Launch Date | I7: Tool Lob Date | J7: C.E Input Data validation | K7: Remarks(C.E) | L7: TRF Plan Date | M7: TRF Act Date | N7: TRF No | O7: Tool Number | P7: Tool Description | Q7: Operation | R7: Complexity | S7: Design (Inhouse|Outsourced ) | T7: TRS Number(Design) | U7: TRS Plan Date(Design) | V7: TRS Act Date (Design) | W7: PR Number (Design) | X7: PR Date (Design) | Y7: PO Date(Design) | Z7: PO No(Design) | AA7: Vendor Info (Design) | AB7: Design Start Date (Plan) | AC7: Design End Date (Plan) | AD7: Design Start Date (Actual) | AE7: Design End Date (Actual) | AF7: Applicability | AG7: Cust. Plan Date | AH7: Cust. Actual Date | AI7: MASPL Tool Design Validation | AJ7: Validation Remarks | AK7: Design Status | AL7: Delay (Design) | AM7: Delay Reason (Design) | AN7: Tool Length | AO7: Tool Width | AP7: Tool Height | AQ7: TL CODE (SAP) | AR7: Manufacturing (Outsourced ) | AS7: TRS (Mfg) | AT7: TRS Plan Date(Mfg) | AU7: TRS Act Date (Mfg) | AV7: PR Number(Mfg) | AW7: PR Date (Mfg) | AX7: PO Date (Mfg) | AY7: PO No (Mfg) | AZ7: Vendor Info (Mfg) | BA7: Mfg Start Date (Plan) | BB7: Mfg End Date (Plan) | BC7: Supplier Commited Date | BD7: Tool Received Date | BE7: Mfg Status | BF7: Delay (Mfg) | BG7: Delay Reason (Mfg) | BH7: MASPL Tooling Quality Acceptance | BI7: MASPL Tool Buy-Off (Mfg) | BJ7: Buy-Off Remarks(Mfg) | BK7: FAI TOOL PROVEOUT | BL7: Proveout Remarks | BM7: ACCEPTANCE / REJECTION CRITERIA | BN7: Tool Handover to Stores | BO7: TOOL LIFE CYCLE | BP7: Validation Frequency | BQ7: Previous Validation Date | BR7: Next Validation Date | BS7: Remarks
A8: 1 | B8: ATLANTIC | C8: ABS | D8: Z5791303430400 | E8: Z579-13034-304-00 | F8: =SUBSTITUTE(SUBSTITUTE(SUBSTITUTE(SUBSTITUTE(E8,",",""),".",""),"-",""),"_","") -> Z5791303430400 | H8: =_xlfn.XLOOKUP(D8,Programs!D:D,Programs!I:I) -> 45491 | I8: =IFERROR((H8-21),"") -> 45470 | J8: Yes | L8: =IFERROR((AB8-22),"") -> 45276 | O8: 48500D57914677200000 | P8: MILLING FIXTURE | Q8: CNC Machining | R8: Medium | S8: IN-HOUSE | T8: N/A | AB8: =IFERROR((AC8-60),"") -> 45298 | AC8: =IFERROR((AT8-15),"") -> 45358 | AD8: 45644 | AE8: 45646 | AF8: No | AI8: Yes | AK8: Completed | AL8: #REF! | AN8: 330 | AO8: 192 | AP8: 103 | AQ8: TL0360090010001 | AR8: OUTSOURCE | AS8: TRS-1762 | AT8: =IFERROR((BA8-7),"") -> 45373 | AU8: 45646 | AV8: 1128571993 | AW8: 45646 | AX8: #REF! | AY8: #REF! | AZ8: #REF! | BA8: =IFERROR((BB8-90),"") -> 45380 | BB8: =IFERROR((H8-21),"") -> 45470 | BC8: #REF! | BD8: 45485 | BE8: Received from Vendor | BF8: #REF! | BP8: 1 year | BQ8: =IF(BD8="","",BD8) -> 45485 | BR8: =IF(BQ8="","",(BQ8+365)) -> 45850
A9: 2 | B9: ATLANTIC | C9: ABS | D9: Z5791303330400 | E9: Z579-13033-304-00 | F9: =SUBSTITUTE(SUBSTITUTE(SUBSTITUTE(SUBSTITUTE(E9,",",""),".",""),"-",""),"_","") -> Z5791303330400 | H9: =_xlfn.XLOOKUP(D9,Programs!D:D,Programs!I:I) -> 45491 | I9: =IFERROR((H9-21),"") -> 45470 | J9: Yes | L9: =IFERROR((AB9-22),"") -> 45276 | O9: 48500D57914677200000 | P9: MILLING FIXTURE | Q9: CNC Machining | R9: Medium | S9: IN-HOUSE | T9: N/A | AB9: =IFERROR((AC9-60),"") -> 45298 | AC9: =IFERROR((AT9-15),"") -> 45358 | AD9: 45644 | AE9: 45646 | AF9: No | AI9: Yes | AK9: Completed | AL9: #REF! | AN9: 330 | AO9: 192 | AP9: 103 | AQ9: TL0360090010001 | AR9: OUTSOURCE | AS9: TRS-1762 | AT9: =IFERROR((BA9-7),"") -> 45373 | AU9: 45646 | AV9: 1128571993 | AW9: 45646 | AX9: #REF! | AY9: #REF! | AZ9: #REF! | BA9: =IFERROR((BB9-90),"") -> 45380 | BB9: =IFERROR((H9-21),"") -> 45470 | BC9: #REF! | BD9: 45490 | BE9: Received from Vendor | BF9: #REF! | BP9: 1 year | BQ9: =IF(BD9="","",BD9) -> 45490 | BR9: =IF(BQ9="","",(BQ9+365)) -> 45855
A10: 3 | B10: ATLANTIC | C10: ABS | D10: Z5791303730400 | E10: Z579-13037-304-00 | F10: =SUBSTITUTE(SUBSTITUTE(SUBSTITUTE(SUBSTITUTE(E10,",",""),".",""),"-",""),"_","") -> Z5791303730400 | H10: =_xlfn.XLOOKUP(D10,Programs!D:D,Programs!I:I) -> 45491 | I10: =IFERROR((H10-21),"") -> 45470 | J10: Yes | L10: =IFERROR((AB10-22),"") -> 45276 | O10: 54100D53931727200000 | P10: PRESS TOOL | Q10: Forming | R10: Medium | S10: IN-HOUSE | T10: N/A | AB10: =IFERROR((AC10-60),"") -> 45298 | AC10: =IFERROR((AT10-15),"") -> 45358 | AD10: 45633 | AE10: 45635 | AF10: No | AI10: Yes | AK10: Completed | AL10: #REF! | AN10: 225 | AO10: 120 | AP10: 71.2 | AQ10: TL0360080010005 | AR10: OUTSOURCE | AS10: TRS-1176 | AT10: =IFERROR((BA10-7),"") -> 45373 | AU10: 45635 | AV10: 1128571993 | AW10: 45547 | AX10: #REF! | AY10: #REF! | AZ10: #REF! | BA10: =IFERROR((BB10-90),"") -> 45380 | BB10: =IFERROR((H10-21),"") -> 45470 | BC10: #REF! | BD10: 45495 | BE10: Received from Vendor | BF10: #REF! | BP10: 1 year | BQ10: =IF(BD10="","",BD10) -> 45495 | BR10: =IF(BQ10="","",(BQ10+365)) -> 45860
A11: 4 | B11: ATLANTIC | C11: ABS | D11: Z5791303530400 | E11: Z579-13035-304-00 | F11: =SUBSTITUTE(SUBSTITUTE(SUBSTITUTE(SUBSTITUTE(E11,",",""),".",""),"-",""),"_","") -> Z5791303530400 | H11: =_xlfn.XLOOKUP(D11,Programs!D:D,Programs!I:I) -> 45491 | I11: =IFERROR((H11-21),"") -> 45470 | J11: Yes | L11: =IFERROR((AB11-22),"") -> 45276 | O11: 54100D53922064200000 | P11: FORM BLOCK | Q11: Forming | R11: Medium | S11: IN-HOUSE | T11: N/A | AB11: =IFERROR((AC11-60),"") -> 45298 | AC11: =IFERROR((AT11-15),"") -> 45358 | AD11: 45644 | AE11: 45646 | AF11: No | AI11: Yes | AK11: Completed | AL11: #REF! | AN11: 128 | AO11: 102 | AP11: 82 | AQ11: TL0360010010003 | AR11: OUTSOURCE | AS11: TRS-1762 | AT11: =IFERROR((BA11-7),"") -> 45373 | AU11: 45646 | AV11: 1128571993 | AW11: 45646 | AX11: #REF! | AY11: #REF! | AZ11: #REF! | BA11: =IFERROR((BB11-90),"") -> 45380 | BB11: =IFERROR((H11-21),"") -> 45470 | BC11: #REF! | BD11: 45470 | BE11: Received from Vendor | BF11: #REF! | BP11: 1 year | BQ11: =IF(BD11="","",BD11) -> 45470 | BR11: =IF(BQ11="","",(BQ11+365)) -> 45835
A12: 5 | B12: ATLANTIC | C12: ABS | D12: Z5791319730300 | E12: Z579-13197-303-00 | F12: =SUBSTITUTE(SUBSTITUTE(SUBSTITUTE(SUBSTITUTE(E12,",",""),".",""),"-",""),"_","") -> Z5791319730300 | H12: =_xlfn.XLOOKUP(D12,Programs!D:D,Programs!I:I) -> 45491 | I12: =IFERROR((H12-21),"") -> 45470 | J12: Yes | L12: =IFERROR((AB12-22),"") -> 45276 | O12: 54100E53911171204000 | P12: FORM BLOCK | Q12: Forming | R12: Medium | S12: IN-HOUSE | T12: N/A | AB12: =IFERROR((AC12-60),"") -> 45298 | AC12: =IFERROR((AT12-15),"") -> 45358 | AD12: 45644 | AE12: 45646 | AF12: No | AI12: Yes | AK12: Completed | AL12: #REF! | AN12: 380 | AO12: 369 | AP12: 57 | AQ12: TL0360010010004 | AR12: OUTSOURCE | AS12: TRS-1762 | AT12: =IFERROR((BA12-7),"") -> 45373 | AU12: 45646 | AV12: 1128571993 | AW12: 45646 | AX12: #REF! | AY12: #REF! | AZ12: #REF! | BA12: =IFERROR((BB12-90),"") -> 45380 | BB12: =IFERROR((H12-21),"") -> 45470 | BC12: #REF! | BD12: 45478 | BE12: Received from Vendor | BF12: #REF! | BP12: 1 year | BQ12: =IF(BD12="","",BD12) -> 45478 | BR12: =IF(BQ12="","",(BQ12+365)) -> 45843
A13: 6 | B13: ATLANTIC | C13: ABS | D13: Z5791303130400 | E13: Z579-13031-304-00 | F13: =SUBSTITUTE(SUBSTITUTE(SUBSTITUTE(SUBSTITUTE(E13,",",""),".",""),"-",""),"_","") -> Z5791303130400 | H13: =_xlfn.XLOOKUP(D13,Programs!D:D,Programs!I:I) -> 45491 | I13: =IFERROR((H13-21),"") -> 45470 | J13: Yes | L13: =IFERROR((AB13-22),"") -> 45276 | O13: 54100A53610044208000 | P13: FORM BLOCK | Q13: Forming | R13: Medium | S13: IN-HOUSE | T13: N/A | AB13: =IFERROR((AC13-60),"") -> 45298 | AC13: =IFERROR((AT13-15),"") -> 45358 | AD13: 45787 | AE13: 45789 | AF13: No | AI13: Yes | AK13: Completed | AL13: #REF! | AN13: 130 | AO13: 92.9 | AP13: 40 | AQ13: TL0360010010053 | AR13: OUTSOURCE | AS13: TRS-1854 | AT13: =IFERROR((BA13-7),"") -> 45373 | AU13: 45789 | AV13: 1129153035 | AW13: 45789 | AX13: #REF! | AY13: #REF! | AZ13: #REF! | BA13: =IFERROR((BB13-90),"") -> 45380 | BB13: =IFERROR((H13-21),"") -> 45470 | BC13: #REF! | BD13: 45496 | BE13: Received from Vendor | BF13: #REF! | BP13: 1 year | BQ13: =IF(BD13="","",BD13) -> 45496 | BR13: =IF(BQ13="","",(BQ13+365)) -> 45861
A14: 7 | B14: ATLANTIC | C14: ABS | D14: Z5391064000000 | E14: Z539-10640-000-00 | F14: =SUBSTITUTE(SUBSTITUTE(SUBSTITUTE(SUBSTITUTE(E14,",",""),".",""),"-",""),"_","") -> Z5391064000000 | H14: =_xlfn.XLOOKUP(D14,Programs!D:D,Programs!I:I) -> 45491 | I14: =IFERROR((H14-21),"") -> 45470 | J14: Yes | L14: =IFERROR((AB14-22),"") -> 45276 | O14: 54100A53610044209000 | P14: FORM BLOCK | Q14: Forming | R14: Medium | S14: IN-HOUSE | T14: N/A | AB14: =IFERROR((AC14-60),"") -> 45298 | AC14: =IFERROR((AT14-15),"") -> 45358 | AD14: 45787 | AE14: 45789 | AF14: No | AI14: Yes | AK14: Completed | AL14: #REF! | AN14: 130 | AO14: 92.9 | AP14: 40 | AQ14: TL0360010010054 | AR14: OUTSOURCE | AS14: TRS-1854 | AT14: =IFERROR((BA14-7),"") -> 45373 | AU14: 45789 | AV14: 1129153035 | AW14: 45789 | AX14: #REF! | AY14: #REF! | AZ14: #REF! | BA14: =IFERROR((BB14-90),"") -> 45380 | BB14: =IFERROR((H14-21),"") -> 45470 | BC14: #REF! | BD14: 45505 | BE14: Received from Vendor | BF14: #REF! | BP14: 1 year | BQ14: =IF(BD14="","",BD14) -> 45505 | BR14: =IF(BQ14="","",(BQ14+365)) -> 45870
A15: 8 | B15: ATLANTIC | C15: ABS | D15: X5393680130300 | E15: X539-36801-303-00 | F15: =SUBSTITUTE(SUBSTITUTE(SUBSTITUTE(SUBSTITUTE(E15,",",""),".",""),"-",""),"_","") -> X5393680130300 | H15: =_xlfn.XLOOKUP(D15,Programs!D:D,Programs!I:I) -> 45491 | I15: =IFERROR((H15-21),"") -> 45470 | J15: Yes | L15: =IFERROR((AB15-22),"") -> 45276 | O15: 48500A53610221316000 | P15: MILLING FIXTURE | Q15: CNC Machining | R15: Simple | S15: IN-HOUSE | T15: N/A | AB15: =IFERROR((AC15-60),"") -> 45298 | AC15: =IFERROR((AT15-15),"") -> 45358 | AD15: 45809 | AE15: 45811 | AF15: No | AI15: Yes | AK15: Completed | AL15: #REF! | AN15: 250 | AO15: 110 | AP15: 25 | AQ15: TL0360090010066 | AR15: OUTSOURCE | AS15: TRS-1875 | AT15: =IFERROR((BA15-7),"") -> 45373 | AU15: 45811 | AV15: 1129250005 | AW15: 45811 | AX15: #REF! | AY15: #REF! | AZ15: #REF! | BA15: =IFERROR((BB15-90),"") -> 45380 | BB15: =IFERROR((H15-21),"") -> 45470 | BC15: #REF! | BD15: 45473 | BE15: Received from Vendor | BF15: #REF! | BP15: 1 year | BQ15: =IF(BD15="","",BD15) -> 45473 | BR15: =IF(BQ15="","",(BQ15+365)) -> 45838
A16: 9 | B16: ATLANTIC | C16: ABS | D16: Z5391067830000 | E16: Z539-10678-300-00 | F16: =SUBSTITUTE(SUBSTITUTE(SUBSTITUTE(SUBSTITUTE(E16,",",""),".",""),"-",""),"_","") -> Z5391067830000 | H16: =_xlfn.XLOOKUP(D16,Programs!D:D,Programs!I:I) -> 45491 | I16: =IFERROR((H16-21),"") -> 45470 | J16: Yes | L16: =IFERROR((AB16-22),"") -> 45276 | O16: 54100D21210684200000 | P16: FORM BLOCK | Q16: Forming | R16: Simple | S16: IN-HOUSE | T16: N/A | AB16: =IFERROR((AC16-60),"") -> 45298 | AC16: =IFERROR((AT16-15),"") -> 45358 | AD16: 45823 | AE16: 45825 | AF16: No | AI16: Yes | AK16: Completed | AL16: #REF! | AN16: 200 | AO16: 160 | AP16: 56.8 | AQ16: TL0360010010080 | AR16: OUTSOURCE | AS16: TRS-1895 | AT16: =IFERROR((BA16-7),"") -> 45373 | AU16: 45825 | AV16: 1129377449 | AW16: 45825 | AX16: #REF! | AY16: #REF! | AZ16: #REF! | BA16: =IFERROR((BB16-90),"") -> 45380 | BB16: =IFERROR((H16-21),"") -> 45470 | BC16: #REF! | BD16: 45480 | BE16: Received from Vendor | BF16: #REF! | BP16: 1 year | BQ16: =IF(BD16="","",BD16) -> 45480 | BR16: =IF(BQ16="","",(BQ16+365)) -> 45845
A17: 10 | B17: ATLANTIC | C17: ABS | D17: Z5393680130400 | E17: Z539-36801-304-00 | F17: =SUBSTITUTE(SUBSTITUTE(SUBSTITUTE(SUBSTITUTE(E17,",",""),".",""),"-",""),"_","") -> Z5393680130400 | H17: =_xlfn.XLOOKUP(D17,Programs!D:D,Programs!I:I) -> 45491 | I17: =IFERROR((H17-21),"") -> 45470 | J17: Yes | L17: =IFERROR((AB17-22),"") -> 45276 | O17: 54100D53230653200000 | P17: FORM BLOCK | Q17: Forming | R17: Simple | S17: IN-HOUSE | T17: N/A | AB17: =IFERROR((AC17-60),"") -> 45298 | AC17: =IFERROR((AT17-15),"") -> 45358 | AD17: 45754 | AE17: 45756 | AF17: No | AI17: Yes | AK17: Completed | AL17: #REF! | AN17: 195 | AO17: 63.1 | AP17: 48 | AQ17: TL0360010010045 | AR17: OUTSOURCE | AS17: TRS-1833 | AT17: =IFERROR((BA17-7),"") -> 45373 | AU17: 45756 | AV17: 1129025298 | AW17: 45756 | AX17: #REF! | AY17: #REF! | AZ17: #REF! | BA17: =IFERROR((BB17-90),"") -> 45380 | BB17: =IFERROR((H17-21),"") -> 45470 | BC17: #REF! | BD17: 45479 | BE17: Received from Vendor | BF17: #REF! | BP17: 1 year | BQ17: =IF(BD17="","",BD17) -> 45479 | BR17: =IF(BQ17="","",(BQ17+365)) -> 45844
A18: 11 | B18: ATLANTIC | C18: ABS | D18: Z5393680130600 | E18: Z539-36801-306-00 | F18: =SUBSTITUTE(SUBSTITUTE(SUBSTITUTE(SUBSTITUTE(E18,",",""),".",""),"-",""),"_","") -> Z5393680130600 | H18: =_xlfn.XLOOKUP(D18,Programs!D:D,Programs!I:I) -> 45491 | I18: =IFERROR((H18-21),"") -> 45470 | J18: Yes | L18: =IFERROR((AB18-22),"") -> 45276 | O18: 54100D53230654200000 | P18: FORM BLOCK | Q18: Forming | R18: Simple | S18: IN-HOUSE | T18: N/A | AB18: =IFERROR((AC18-60),"") -> 45298 | AC18: =IFERROR((AT18-15),"") -> 45358 | AD18: 45754 | AE18: 45756 | AF18: No | AI18: Yes | AK18: Completed | AL18: #REF! | AN18: 165 | AO18: 43 | AP18: 52 | AQ18: TL0360010010043 | AR18: OUTSOURCE | AS18: TRS-1833 | AT18: =IFERROR((BA18-7),"") -> 45373 | AU18: 45756 | AV18: 1129025298 | AW18: 45756 | AX18: #REF! | AY18: #REF! | AZ18: #REF! | BA18: =IFERROR((BB18-90),"") -> 45380 | BB18: =IFERROR((H18-21),"") -> 45470 | BC18: #REF! | BD18: 45476 | BE18: Received from Vendor | BF18: #REF! | BP18: 1 year | BQ18: =IF(BD18="","",BD18) -> 45476 | BR18: =IF(BQ18="","",(BQ18+365)) -> 45841
J21: C.E Input Data validation | P21: Tool Description | R21: Complexity | S21: Sourcing | AI21: MASPL Tool Design Validation | AK21: Tool Design Status | AM21: Design Delay | BE21: Manufacturing Status | BG21: Manufacturing delay | BI21: MASPL Tool Buy-Off (Mfg) | BK21: FAI TOOL PROVEOUT
J22: YES | P22: DRILL JIG | R22: Simple | S22: IN-HOUSE | AI22: YES | AK22: Completed | AM22: Requirements not finalized | BE22: Completed (IN-HOUSE) | BG22: RFQ / quotation delay | BI22: YES | BK22: YES
J23: NO | P23: CHECKING FIXTURE | R23: Medium | S23: OUTSOURCE | AI23: NO | AK23: Work In Progress | AM23: Frequent design changes | BE23: Work In Progress at Vendor | BG23: PO release delay | BI23: NO | BK23: NO
P24: CHECK FIXTURE | R24: Complex | S24: CUSTOMER | AK24: Delayed | AM24: Customer clarification pending | BE24: Delayed by Vendor | BG24: Vendor capacity constraints
P25: FORM BLOCK | R25: Very Complex | S25: YET TO PLAN | AK25: On Track | AM25: Input data awaited | BE25: On Track at Supplier | BG25: Material procurement delay by vendor
P26: FORM BLOCK-2 | AK26: Under Review | AM26: Dependency on other teams | BE26: RFQ Sent / Awaiting Quote | BG26: Supplier manufacturing backlog
P27: PRESS TOOL | AK27: Pending Approval | AM27: Review comments not closed | BE27: Under PO Creation | BG27: Quality issues at vendor
P28: MILLING FIXTURE | AK28: On Hold | AM28: Approval delay | BE28: Material Procurement by Vendor | BG28: Rework at supplier
P29: HOLDING FIXTURE/MILLING FIXTURE | AK29: Blocked | AM29: Resource unavailability | BE29: Approval Pending | BG29: Inspection / approval delay
P30: INSPECTION TEMPLATE | AK30: Rework Required | AM30: Tool/spec changes | BE30: Quality Issue at Supplier | BG30: Dispatch delay from vendor
P31: SHOP AID | AK31: Cancelled | AM31: Rework due to errors | BE31: Rework at Vendor | BG31: Insufficient Data
P32: HAND FORM BLOCK | AK32: Not Started | AM32: Customer Data Pack Revised | BE32: Dispatch Pending from Vendor | BG32: Supplier-side hold
P33: FORM BLOCK | AK33: Design Shared to Customer | BE33: In Transit | BG33: Communication delay with vendor
P34: FORM BLOCK STAGE-2 | BE34: Received from Vendor
P35: HOLDING FIXTURE | BE35: PO Issue
P36: BEARING PRESSING TOOL | BE36: Design Not Released For Manufacturing
P37: PRESS SWAGING TOOL | BE37: Hold
P38: BEARING LOAD TESTING | BE38: Source Inspection required
P39: BEARING LOAD TESTING TOOL
P40: HAND FORM TOOL
P41: STRECH FORMING TOOL
P42: FORM BLOCK(stage-1)
P43: FORM BLOCK(stage-2)
P44: HAND FORM
P45: STRETCH FORM TOOL
...

Sheet SCM
B3: MASTER TRACKER | C3: TOOLING TRACKER | D3: TOOLING TRACKER | E3: SAP | F3: SAP | G3: TOOLING TRACKER | H3: TOOLING TRACKER | J3: MANUAL | K3: SAP | L3: SAP | M3: MANUAL | N3: MANUAL | O3: MANUAL | P3: MANUAL
A5: SI NO | B5: Customer / Department | C5: TRS | D5: PR No. | E5: Item of requisition | F5: PR + Data Sharing date | G5: TL code | H5: Description | I5: QTY | J5: Supplier | K5: PO No. | L5: PO Date | M5: Current Status/ Live Status | N5: First cut ETA | O5: Updated ETA | P5: Remarks
A6: 1 | B6: ABS | C6: TRS-1762 | D6: 1128571993 | E6: 10 | F6: 45646 | G6: TL0360090010001 | H6: MILLING FIXTURE | I6: 1 | J6: Inovit Aerospace Solutions | K6: 12300261382 | L6: 45661 | M6: Delivered | N6: 45470 | O6: 45485
A7: 2 | B7: ABS | C7: TRS-1762 | D7: 1128571993 | E7: 20 | F7: 45646 | G7: TL0360090010001 | H7: MILLING FIXTURE | I7: 1 | J7: Inovit Aerospace Solutions | K7: 12300261382 | L7: 45661 | M7: Delivered | N7: 45470 | O7: 45490
A8: 3 | B8: ABS | C8: TRS-1176 | D8: 1128571993 | E8: 10 | F8: 45547 | G8: TL0360080010005 | H8: PRESS TOOL | I8: 1 | J8: Planetto Tooltech | K8: 12300261538 | L8: 45562 | M8: Delivered | N8: 45470 | O8: 45495
A9: 4 | B9: ABS | C9: TRS-1762 | D9: 1128571993 | E9: 20 | F9: 45646 | G9: TL0360010010003 | H9: FORM BLOCK | I9: 1 | J9: Planetto Tooltech | K9: 12300261538 | L9: 45661 | M9: Delivered | N9: 45470 | O9: 45470
A10: 5 | B10: ABS | C10: TRS-1762 | D10: 1128571993 | E10: 30 | F10: 45646 | G10: TL0360010010004 | H10: FORM BLOCK | I10: 1 | J10: Planetto Tooltech | K10: 12300261538 | L10: 45661 | M10: Delivered | N10: 45470 | O10: 45478
A11: 6 | B11: ABS | C11: TRS-1854 | D11: 1129153035 | E11: 40 | F11: 45789 | G11: TL0360010010053 | H11: FORM BLOCK | I11: 1 | J11: Planetto Tooltech | K11: 12300261538 | L11: 45804 | M11: Delivered | N11: 45470 | O11: 45496
A12: 7 | B12: ABS | C12: TRS-1854 | D12: 1129153035 | E12: 50 | F12: 45789 | G12: TL0360010010054 | H12: FORM BLOCK | I12: 1 | J12: Planetto Tooltech | K12: 12300261538 | L12: 45804 | M12: Delivered | N12: 45470 | O12: 45505
A13: 8 | B13: ABS | C13: TRS-1875 | D13: 1129250005 | E13: 60 | F13: 45811 | G13: TL0360090010066 | H13: MILLING FIXTURE | I13: 1 | J13: Planetto Tooltech | K13: 12300261538 | L13: 45826 | M13: Delivered | N13: 45470 | O13: 45473
A14: 9 | B14: ABS | C14: TRS-1895 | D14: 1129377449 | E14: 10 | F14: 45825 | G14: TL0360010010080 | H14: FORM BLOCK | I14: 1 | J14: Planetto Tooltech | K14: 12300262066 | L14: 45840 | M14: Delivered | N14: 45470 | O14: 45480
A15: 10 | B15: ABS | C15: TRS-1833 | D15: 1129025298 | E15: 20 | F15: 45756 | G15: TL0360010010045 | H15: FORM BLOCK | I15: 1 | J15: Planetto Tooltech | K15: 12300262066 | L15: 45771 | M15: Delivered | N15: 45470 | O15: 45479
A16: 11 | B16: ABS | C16: TRS-1833 | D16: 1129025298 | E16: 30 | F16: 45756 | G16: TL0360010010043 | H16: FORM BLOCK | I16: 1 | J16: Planetto Tooltech | K16: 12300262066 | L16: 45771 | M16: Delivered | N16: 45470 | O16: 45476

Sheet PPC
D4: formula = today()- previous operation confirmation date | N4: SAP routing - last operation | O4: Based SAP routing manual check for assy WC
A5: SAP DATA | B5: SAP DATA | C5: SAP DATA | D5: SAP | E5: MASTER TRACKER | F5: MANUAL UPDATED | G5: SAP | H5: SAP | I5: MANUAL | J5: Manual | K5: Master tracker | L5: MANUAL | M5: MANUAL | N5: PROCESS SHEET | O5: Manual | P5: Manual | Q5: Manual (From the date of WO launch) | R5: Manual | S5: SAP | T5: SAP | U5: MASTER TRACKER | V5: MASTER TRACKER | W5: FORMULA | X5: SAP | Y5: SAP | Z5: Master tracker | AA5: Formula | AC5: SAP STATUS | AD5: SAP STATUS | AE5: SAP STATUS | AF5: SAP STATUS | AG5: SAP STATUS | AH5: SAP STATUS | AI5: SAP STATUS | AJ5: SAP STATUS | AK5: SAP STATUS | AL5: SAP STATUS | AM5: SAP STATUS | AN5: SAP STATUS | AO5: SAP STATUS | AP5: SAP STATUS | AQ5: SAP STATUS | AR5: SAP STATUS | AS5: SAP STATUS | AT5: SAP STATUS | AU5: SAP STATUS | AV5: SAP STATUS | AW5: SAP STATUS | AX5: SAP STATUS | AY5: SAP STATUS | AZ5: SAP STATUS | BA5: SAP STATUS | BB5: SAP STATUS | BC5: SAP STATUS | BD5: SAP STATUS | BE5: SAP STATUS | BF5: SAP STATUS | BG5: SAP STATUS | BH5: SAP STATUS
A7: SAP PN# | B7: WO | C7: SAP STATUS | D7: AGEING | E7: PROJECT | F7: ISSUES | G7: QTY | H7: KMDF/ KMFI | I7: ACTION STATUS | J7: WORK CATEGORY | K7: PRIORITY | L7: ISSUE SUMMARY | M7: RESP | N7: DP/CP | O7: ASSY | P7: EDC | Q7: WO ACTIVE DAYS | R7: PO Check | S7: Next Operation Cat | T7: Next Operation Desc | U7: CUSTOMER | V7: PROJECT NOMENCLATURE | W7: OPN PENDING | X7: RM STOCK CHECK | Y7: RM CODE | Z7: PROJECT2 | AA7: COMPLETION% | AB7: HANDOVER | AC7: 1 | AD7: 2 | AE7: 3 | AF7: 4 | AG7: 5 | AH7: 6 | AI7: 7 | AJ7: 8 | AK7: 9 | AL7: 10 | AM7: 11 | AN7: 12 | AO7: 13 | AP7: 14 | AQ7: 15 | AR7: 16 | AS7: 17 | AT7: 18 | AU7: 19 | AV7: 20 | AW7: 21 | AX7: 22 | AY7: 23 | AZ7: 24 | BA7: 25 | BB7: 26 | BC7: 27 | BD7: 28 | BE7: 29 | BF7: 30 | BG7: 31 | BH7: 32
A8: Z5791303430400 | B8: 21008325 | C8: FINISHED GOODS STORAGE | D8: 532 | E8: ABS | F8: Waiting for approval | G8: 7 | H8: KMFI | I8: OPEN | J8: FG | K8: PART SUBMITTED | L8: FAI Approval | M8: FG | N8: DP | O8: NO | P8: 0 | Q8: 581 | R8: YES | S8: FG | T8: FINISHED GOODS STORAGE | U8: ABS | V8: ABS | W8: 2 | X8: OK | Y8: #N/A | Z8: ABS | AA8: 0.9047619 | AB8: pending | AC8: RS-RM-01 | AD8: SMROCELL | AE8: SM-DB-01 | AF8: SM-DB-03 | AG8: QA-BI-01 | AH8: SMHTCELL | AI8: SMHTCELL | AJ8: HT-CS-02 | AK8: SMPBCELL | AL8: SM-HP-01 | AM8: SM-CS-01 | AN8: SMAOCELL | AO8: SMAOCELL | AP8: QA-CI-01 | AQ8: QA-HT-01 | AR8: ND-FP-01 | AS8: ST-CA-02 | AT8: QA-ST-01 | AU8: PM-PI-01 | AV8: QA-FIHERE | AW8: RS-FG-01
A9: Z5791303330400 | B9: 21009970 | C9: FINISHED GOODS STORAGE | D9: 440 | E9: ABS | G9: 3 | H9: KMFI | I9: Closed | J9: FG | K9: PART SUBMITTED | L9: FAI Approval | M9: FG | N9: DP | O9: YES | Q9: 493 | R9: YES | S9: FG | T9: FINISHED GOODS STORAGE | U9: ABS | V9: ABS | W9: 1 | X9: OK | Y9: #N/A | Z9: ABS | AA9: 0.95 | AB9: Completed | AC9: RS-RM-01 | AD9: SMROCELL | AE9: SM-DB-01 | AF9: SM-DB-03 | AG9: QA-BI-01 | AH9: SMPBCELL | AI9: QA-CI-01 | AJ9: ST-TA-04 | AK9: QA-ST-01 | AL9: ST-PS-01 | AM9: QA-PS-01 | AN9: ST-PS-01 | AO9: ST-TU-01 | AP9: QA-PS-01 | AQ9: RS-HD-01 | AR9: EQUIP-01 | AS9: EQ-QA-01 | AT9: AS-PM-02 | AU9: QA-FI | AV9: RS-FG-01HERE
A10: Z5791303730400 | B10: 21012070 | C10: FINISHED GOODS STORAGE | D10: 354 | E10: ABS | F10: Waiting for approval | G10: 2 | H10: KMFI | I10: OPEN | J10: FG | K10: PART SUBMITTED | L10: FAI Approval | M10: FG | N10: DP | O10: NO | P10: 0 | Q10: 396 | R10: YES | S10: FG | T10: FINISHED GOODS STORAGE | U10: ABS | V10: ABS | W10: 2 | X10: OK | Y10: #N/A | Z10: ABS | AA10: 0.9047619 | AB10: Completed | AC10: RS-RM-01 | AD10: SMROCELL | AE10: SM-DB-01 | AF10: SM-DB-03 | AG10: QA-BI-01 | AH10: SMHTCELL | AI10: SMHTCELL | AJ10: HT-CS-02 | AK10: SMPBCELL | AL10: QA-CI-01 | AM10: QA-HT-01 | AN10: ST-TA-04 | AO10: QA-ST-01 | AP10: ST-PS-01 | AQ10: QA-PS-01 | AR10: ST-PS-01 | AS10: ST-TU-01 | AT10: QA-PS-01 | AU10: PM-PI-01 | AV10: QA-FIHERE | AW10: RS-FG-01
A11: Z5791303530400 | B11: 21011882 | C11: FINISHED GOODS STORAGE | D11: 340 | E11: ABS | G11: 2 | H11: KMFI | I11: OPEN | J11: FG | K11: PART SUBMITTED | L11: FAI Approval | M11: FG | N11: DP | O11: YES | P11: 0 | Q11: 396 | R11: NO | S11: FG | T11: FINISHED GOODS STORAGE | U11: ABS | V11: ABS | W11: 12 | X11: NOT OK | Y11: RA1M7011861601 | Z11: ABS | AA11: 0.53846154 | AB11: #N/A | AC11: RS-RM-01 | AD11: SM-WL-01 | AE11: SM-WL-01 | AF11: SM-CS-01 | AG11: QA-WL-01 | AH11: QA-CI-02 | AI11: ND-FP-01 | AJ11: ST-CA-02 | AK11: QA-ST-01 | AL11: ST-PS-01 | AM11: QA-PS-01 | AN11: ST-TC-01 | AO11: ST-TU-01 | AP11: QA-PS-01 | AQ11: RS-HD-01HERE | AR11: EQUIP-01 | AS11: AS-SE-01 | AT11: AS-SE-01 | AU11: EQUIP-01 | AV11: EQ-QA-01 | AW11: AS-PS-01 | AX11: AS-PM-02 | AY11: QA-FI | AZ11: AS-PM-02 | BA11: AS-PS-02 | BB11: RS-FG-01
A12: Z5791319730300 | B12: 21012799 | C12: FINISHED GOODS STORAGE | D12: 311 | E12: ABS | F12: Waiting for approval | G12: 4 | H12: KMFI | I12: OPEN | J12: FG | K12: PART SUBMITTED | L12: FAI Approval | M12: FG | N12: DP | O12: YES | P12: 0 | Q12: 351 | R12: YES | S12: FG | T12: FINISHED GOODS STORAGE | U12: ABS | V12: ABS | W12: 2 | X12: OK | Y12: #N/A | Z12: ABS | AA12: 0.92307692 | AB12: Completed | AC12: RS-RM-01 | AD12: SMROCELL | AE12: SM-DB-01 | AF12: SM-DB-03 | AG12: QA-BI-01 | AH12: SMPBCELL | AI12: QA-CI-01 | AJ12: ST-MA-01 | AK12: QA-ST-01 | AL12: ST-TA-04 | AM12: QA-ST-01 | AN12: ST-PS-01 | AO12: ST-UM-01 | AP12: ST-TU-01 | AQ12: QA-PS-01 | AR12: RS-HD-01 | AS12: EQUIP-01 | AT12: AS-CD-01 | AU12: EQUIP-01 | AV12: EQ-QA-01 | AW12: AS-PS-01 | AX12: AS-QP-01 | AY12: ST-UM-01 | AZ12: AS-PM-02 | BA12: QA-FIHERE | BB12: RS-FG-01
A13: Z5791303130400 | B13: 21013435 | C13: FINISHED GOODS STORAGE | D13: 302 | E13: ABS | F13: Waiting for approval | G13: 2 | H13: KMFI | I13: OPEN | J13: FG | K13: PART SUBMITTED | L13: FAI Approval | M13: FG | N13: DP | O13: NO | P13: 0 | Q13: 323 | R13: YES | S13: FG | T13: FINISHED GOODS STORAGE | U13: ABS | V13: ABS | W13: 2 | X13: OK | Y13: #N/A | Z13: ABS | AA13: 0.86666667 | AB13: Completed | AC13: RS-RM-01 | AD13: SMROCELL | AE13: SM-DB-01 | AF13: SM-DB-03 | AG13: QA-CI-01 | AH13: ST-TA-04 | AI13: QA-ST-01 | AJ13: ST-PS-01 | AK13: QA-PS-01 | AL13: ST-PS-01 | AM13: ST-TU-01 | AN13: QA-PS-01 | AO13: PM-PI-01 | AP13: QA-FIHERE | AQ13: RS-FG-01
A14: Z5391064000000 | B14: 21013552 | C14: FINISHED GOODS STORAGE | D14: 256 | E14: ABS | F14: Waiting for approval | G14: 4 | H14: KMFI | I14: OPEN | J14: FG | K14: PART SUBMITTED | L14: FAI Approval | M14: FG | N14: DP | O14: NO | P14: 0 | Q14: 291 | R14: YES | S14: FG | T14: FINISHED GOODS STORAGE | U14: ABS | V14: ABS | W14: 2 | X14: OK | Y14: #N/A | Z14: ABS | AA14: 0.91304348 | AB14: Completed | AC14: RS-RM-01 | AD14: SMROCELL | AE14: SM-DB-01 | AF14: SM-DB-03 | AG14: QA-BI-01 | AH14: SMHTCELL | AI14: SMHTCELL | AJ14: HT-CS-02 | AK14: SMPBCELL | AL14: SM-TR-01 | AM14: SMPBCELL | AN14: QA-CI-01 | AO14: QA-HT-01 | AP14: ST-TA-04 | AQ14: QA-ST-01 | AR14: ST-PS-01 | AS14: QA-PS-01 | AT14: ST-PS-01 | AU14: ST-TU-01 | AV14: QA-PS-01 | AW14: PM-PI-01 | AX14: QA-FIHERE | AY14: RS-FG-01
A15: X5393680130300 | B15: 21013403 | C15: FINISHED GOODS STORAGE | D15: 254 | E15: ABS | F15: Engg Review | G15: 6 | H15: KMFI | I15: OPEN | J15: FG | K15: PART SUBMITTED | L15: FAI Approval | M15: FG | N15: DP | O15: NO | P15: 0 | Q15: 297 | R15: NO | S15: FG | T15: FINISHED GOODS STORAGE | U15: ABS | V15: ABS | W15: 2 | X15: NOT OK | Y15: RM0010012480005 | Z15: ABS | AA15: 0.91666667 | AB15: Completed | AC15: RS-RM-01 | AD15: SMROCELL | AE15: SM-DB-01 | AF15: SM-DB-03 | AG15: QA-BI-01 | AH15: SMHTCELL | AI15: SMHTCELL | AJ15: HT-CS-02 | AK15: SMPBCELL | AL15: SM-HF-01 | AM15: HT-AO-02 | AN15: QA-CI-02 | AO15: QA-HT-01 | AP15: ND-FP-01 | AQ15: ST-TA-04 | AR15: QA-ST-01 | AS15: ST-PS-01 | AT15: QA-PS-01 | AU15: ST-PS-01 | AV15: ST-TU-01 | AW15: QA-PS-01 | AX15: PM-PI-01 | AY15: QA-FIHERE | AZ15: RS-FG-01
A16: Z5391067830000 | B16: 21013505 | C16: FINISHED GOODS STORAGE | D16: 251 | E16: ABS | F16: Parts are with Engg_Abhishek,PO not available mail has sent from Engg to teco the part | G16: 5 | H16: KMFI | I16: OPEN | J16: FG | K16: PART SUBMITTED | L16: FAI Approval | M16: FG | N16: DP | O16: YES | P16: 0 | Q16: 294 | R16: NO | S16: FG | T16: FINISHED GOODS STORAGE | U16: ABS | V16: ABS | W16: 14 | X16: NOT OK | Y16: RM5060610290029 | Z16: ABS | AA16: 0.5625 | AB16: #N/A | AC16: RS-RM-01 | AD16: SM-RO-03 | AE16: SM-DB-03 | AF16: SM-DB-01 | AG16: QA-CI-02 | AH16: ST-MA-01 | AI16: QA-ST-01 | AJ16: ST-MA-01 | AK16: QA-ST-01 | AL16: ST-CA-02 | AM16: QA-ST-01 | AN16: ST-PS-01 | AO16: QA-PS-01 | AP16: ST-TC-01 | AQ16: ST-TU-01 | AR16: ST-MA-01 | AS16: QA-PS-01 | AT16: RS-HD-01 | AU16: EQUIP-01HERE | AV16: AS-CD-02 | AW16: AS-SE-01 | AX16: AS-SE-01 | AY16: EQUIP-01 | AZ16: EQ-QA-01 | BA16: AS-SE-01 | BB16: AS-SE-01 | BC16: EQ-QA-01 | BD16: AS-PM-02 | BE16: QA-FI | BF16: AS-PM-02 | BG16: AS-PS-02 | BH16: RS-FG-01
A17: Z5393680130400 | B17: 21014390 | C17: FINISHED GOODS STORAGE | D17: 223 | E17: ABS | F17: Drawing Updating | G17: 8 | H17: KMFI | I17: OPEN | J17: FG | K17: PART SUBMITTED | L17: FAI Approval | M17: FG | N17: CP | O17: NO | P17: 0 | Q17: 255 | R17: YES | S17: FG | T17: FINISHED GOODS STORAGE | U17: ABS | V17: ABS | W17: 2 | X17: OK | Y17: #N/A | Z17: ABS | AA17: 0.88235294 | AB17: pending | AC17: RS-RM-01 | AD17: SMROCELL | AE17: SM-DB-01 | AF17: SM-DB-03 | AG17: QA-BI-01 | AH17: SMPBCELL | AI17: QA-CI-01 | AJ17: ST-CC-01 | AK17: QA-ST-01 | AL17: ST-PS-01 | AM17: QA-PS-01 | AN17: ST-PS-01 | AO17: ST-TU-01 | AP17: QA-PS-01 | AQ17: PM-PI-01 | AR17: QA-FIHERE | AS17: RS-SF-01
A18: Z5393680130600 | B18: 21014462 | C18: FINISHED GOODS STORAGE | D18: 218 | E18: ABS | F18: Engg issdue_Wrong hardware loaded | G18: 4 | H18: KMFI | I18: OPEN | J18: FG | K18: PART SUBMITTED | L18: FAI Approval | M18: FG | N18: DP | O18: YES | P18: 0 | Q18: 235 | R18: YES | S18: FG | T18: FINISHED GOODS STORAGE | U18: ABS | V18: ABS | W18: 6 | X18: NOT OK | Y18: RM5171030650065 | Z18: ABS | AA18: 0.66666667 | AB18: pending | AC18: RS-RM-01 | AD18: SMROCELL | AE18: SM-DB-01 | AF18: SM-DB-03 | AG18: QA-BI-01 | AH18: SMPBCELL | AI18: QA-CI-01 | AJ18: ST-TA-04 | AK18: QA-ST-01 | AL18: ST-PS-01 | AM18: ST-TU-01 | AN18: QA-PS-01 | AO18: RS-SF-01HERE | AP18: EQUIP-01 | AQ18: EQ-QA-01 | AR18: AS-PM-02 | AS18: QA-FI | AT18: RS-FG-01
C21: Issue of raw material | D21: for production | J21: WORK CATEGORY | M21: RESP | O21: ASSY
J22: COMP-INSP | M22: ASSY | O22: YES
J23: COMP | M23: ASSY-INSP | O23: NO
J24: SST | M24: Engineering
J25: O/S | M25: COMP
J26: FINSP | M26: COMP-INSP
J27: FG | M27: Program
J28: ASSY-INSP | M28: Program
J29: ASSY | M29: FG
J30: RM-STORE | M30: FINSP
J31: SST-INSP | M31: HT-INSP
J32: HT-INSP | M32: LOADING
J33: SFG | M33: O/S
J34: WELD-INSP | M34: Maintenance
J35: CMM | M35: PPC
... J37: INW-INSP | M37: Program
M38: Quality
M39: RM-STORE
M40: SCM
M41: SFG
M42: SST
M43: SST-INSP
M44: #REF!

Sheet Quality
B3: Manual | C3: Formula - redundant | D3: Formula - redundant | E3: From Programs | F3: From Programs | G3: To Check | H3: From Programs | I3: From Programs | J3: Manual drop down | K3: Manual text | L3: Manual drop down
B5: Date | C5: Month | D5: Week | E5: Customer | F5: Part Number | G5: Type | H5: Work order number | I5: Order Type | J5: Current Status | K5: Remarks | L5: D/C
B6: 45561 | C6: SEPTEMBER | D6: 36 | E6: ATLANTIC | F6: Z5791303430400 | H6: 21002672 | I6: FAI | J6: Approved | L6: CP
B7: 45560 | C7: SEPTEMBER | D7: 36 | E7: ATLANTIC | F7: Z5791303330400 | H7: 21002756 | I7: FAI | J7: Approved | L7: CP
B8: 45561 | C8: SEPTEMBER | D8: 36 | E8: ATLANTIC | F8: Z5791303730400 | H8: 21014016 | I8: FAI | J8: Approved | L8: DP
B9: 45555 | C9: SEPTEMBER | D9: 35 | E9: ATLANTIC | F9: Z5791303530400 | H9: 21011803 | I9: FAI | J9: Approved | L9: DP
B10: 45559 | C10: SEPTEMBER | D10: 36 | E10: ATLANTIC | F10: Z5791319730300 | H10: 21005043 | I10: FAI | J10: Approved | L10: DP
B11: 45561 | C11: SEPTEMBER | D11: 36 | E11: ATLANTIC | F11: Z5791303130400 | H11: 21003087 | I11: FAI | J11: Approved | L11: DP
B12: 45559 | C12: SEPTEMBER | D12: 36 | E12: ATLANTIC | F12: Z5391064000000 | H12: 21007077 | I12: FAI | J12: Approved | L12: DP
B13: 45560 | C13: SEPTEMBER | D13: 36 | E13: ATLANTIC | F13: X5393680130300 | H13: 21009445 | I13: FAI | J13: Waiting for approval | L13: DP
B14: 45554 | C14: SEPTEMBER | D14: 35 | E14: ATLANTIC | F14: Z5391067830000 | H14: 21003861 | I14: FAI | J14: Approved | L14: DP
B15: 45560 | C15: SEPTEMBER | D15: 36 | E15: ATLANTIC | F15: Z5393680130400 | H15: 21001863 | I15: FAI | J15: Approved | L15: DP
B16: 45560 | C16: SEPTEMBER | D16: 36 | E16: ATLANTIC | F16: Z5393680130600 | H16: 21003799 | I16: FAI | J16: Approved | L16: DP
J18: Current Status | L18: D/C
J19: Approved | L19: CP
J20: Waiting For Approval | L20: DP
J21: Issues

Sheet Engineering_Dashboard
B4: =TODAY() -> 46295 | D4: ENGINEERING DASH BOARD-ASA (All Waves)
B5: Project & Scope | D5: GATE 1 | F5: GATE 2 | H5: GATE 3 | J5: Customer Approvals | T5: GATE 4 | X5: Gate 5 | AJ5: Gate 6 (Launch Clerance) | AS5: GATE 7 | AX5: Gate 8 | BC5: Remarks
B6: Project | C6: Scope | D6: TDP Available | E6: TDP Pending | F6: Feasibility Completed | G6: Feasibility Pending | H6: P-BOM Creation completed (RM, HW, Consumables) | I6: P-BOM Creation Pending | J6: SST Approval Completed | K6: SST Approval Pending | L6: LAI Approval Completed | M6: LAI Approval Pending | N6: FPQ Approval Completed | O6: FPQ Approval Pending | P6: Tool Concept Approved | Q6: Tool Concept App.Pending | R6: Tool Design Approved | S6: Tool Design App.Pending | T6: Conncurrence completed | U6: Concurrence Pending | V6: TRF Given | W6: TRF Not Given | X6: 3D Model Completed | Y6: 3D Model Pending | Z6: NCP Completed | AA6: NCP Pending | AB6: Tool Concept Completed | AC6: Tool Concept Pending | AD6: Tool Design Completed | AE6: Tool Design Pending | AF6: Tool Fab. Completed | AG6: Tool Fab. Pending | AH6: Outsourcing Received | AI6: Outsourcing Pending | AJ6: LC Given | AK6: Material Cut | AL6: LC Pending | AM6: ME WIP | AN6: TQ Dep. (Launch) | AO6: RM Dep. | AP6: BOI Dep. | AQ6: CP WIP | AR6: OUTSOURCE (Dossier) Total Scope | AS6: FAI Submitted | AT6: FAI Approval Pending | AU6: FAI Sumission Pending | AV6: TQ Dep. (WIP) | AW6: Other Dep. | AX6: Production Handover Pending | AY6: Production Handover Completed | AZ6: ≤ 3 Batches | BA6: > 3 Batches | BB6: Cutover given to ASA
B7: ASA NPI-1.1 | C7: 148 | D7: 146 | E7: 2 | F7: 140 | G7: 8 | H7: 139 | I7: 9 | J7: 148 | K7: 0 | L7: 148 | M7: 0 | N7: 142 | O7: 0 | P7: 136 | Q7: 6 | R7: 136 | S7: 6 | T7: 136 | U7: 12 | V7: 136 | W7: 0 | X7: 136 | Y7: 6 | AB7: 136 | AC7: 6 | AD7: 136 | AE7: 6 | AF7: 136 | AG7: 6 | AJ7: 131 | AK7: 131 | AL7: 17 | AM7: 11 | AN7: 6 | AO7: 0 | AP7: 0 | AQ7: 0 | AR7: 0 | AS7: 130 | AU7: 18 | AV7: 0 | AX7: 13 | AY7: 117 | AZ7: 68 | BA7: 26
B8: ASA W1 | C8: 53 | D8: 53 | E8: 0 | F8: 53 | G8: 0 | H8: 53 | I8: 0 | J8: 53 | K8: 0 | L8: 52 | M8: 1 | N8: 53 | O8: 0 | P8: 53 | Q8: 0 | R8: 53 | S8: 0 | T8: 53 | U8: 0 | V8: 53 | W8: 0 | X8: 53 | Y8: 0 | AB8: 53 | AC8: 0 | AD8: 53 | AE8: 0 | AF8: 51 | AG8: 2 | AJ8: 53 | AK8: 52 | AL8: 1 | AM8: 0 | AN8: 1 | AO8: 0 | AP8: 0 | AQ8: 0 | AR8: 0 | AS8: 50 | AU8: 3 | AV8: 2 | AX8: 0 | AY8: 50 | AZ8: 5 | BA8: 38
B9: ASA W2 | C9: 618 | D9: 618 | E9: 0 | F9: 618 | G9: 0 | H9: 618 | I9: 0 | J9: 614 | K9: 4 | L9: 610 | M9: 8 | N9: 618 | O9: 4 | P9: 618 | Q9: 0 | R9: 616 | S9: 2 | T9: 618 | U9: 0 | V9: 618 | W9: 0 | X9: 616 | Y9: 2 | AB9: 618 | AC9: 0 | AD9: 617 | AE9: 1 | AF9: 615 | AG9: 3 | AJ9: 610 | AK9: 610 | AL9: 8 | AM9: 1 | AN9: 3 | AO9: 0 | AP9: 0 | AQ9: 0 | AR9: 0 | AS9: 599 | AU9: 19 | AV9: 0 | AX9: 8 | AY9: 591 | AZ9: 163 | BA9: 294
B10: ASA W3A | C10: 313 | D10: 313 | E10: 0 | F10: 313 | G10: 0 | H10: 313 | I10: 0 | J10: 313 | K10: 0 | L10: 307 | M10: 6 | N10: 311 | O10: 2 | P10: 313 | Q10: 0 | R10: 313 | S10: 0 | T10: 313 | U10: 0 | V10: 313 | W10: 0 | X10: 313 | Y10: 0 | AB10: 313 | AC10: 0 | AD10: 313 | AE10: 2 | AF10: 296 | AG10: 17 | AJ10: 291 | AK10: 288 | AL10: 22 | AM10: 19 | AN10: 0 | AO10: 1 | AP10: 1 | AQ10: 1 | AR10: 41 | AS10: 274 | AU10: 39 | AV10: 3 | AX10: 36 | AY10: 238 | AZ10: 0 | BA10: 0
B11: ASA W3B | C11: 276 | D11: 276 | E11: 0 | F11: 276 | G11: 0 | H11: 276 | I11: 0 | J11: 276 | K11: 0 | L11: 275 | M11: 1 | N11: 274 | O11: 0 | P11: 275 | Q11: 0 | R11: 212 | S11: 64 | T11: 276 | U11: 0 | V11: 276 | W11: 0 | X11: 250 | Y11: 26 | AB11: 276 | AC11: 0 | AD11: 261 | AE11: 15 | AF11: 250 | AG11: 48 | AJ11: 213 | AK11: 202 | AL11: 63 | AM11: 38 | AN11: 14 | AO11: 9 | AP11: 2 | AQ11: 0 | AR11: 232 | AS11: 167 | AU11: 109 | AV11: 2 | AX11: 60 | AY11: 107 | AZ11: 0 | BA11: 0
B12: ASA W3C | C12: 351 | D12: 351 | E12: 0 | F12: 351 | G12: 0 | H12: 351 | I12: 0 | J12: 351 | K12: 0 | L12: 310 | M12: 41 | N12: 321 | O12: 0 | P12: 351 | Q12: 0 | R12: 317 | S12: 34 | T12: 351 | U12: 0 | V12: 351 | W12: 0 | X12: 324 | Y12: 27 | AB12: 351 | AC12: 0 | AD12: 317 | AE12: 34 | AF12: 317 | AG12: 34 | AJ12: 279 | AK12: 273 | AL12: 70 | AM12: 58 | AN12: 8 | AO12: 4 | AP12: 0 | AQ12: 0 | AR12: 307 | AS12: 184 | AU12: 167 | AV12: 15 | AX12: 179 | AY12: 5 | AZ12: 0 | BA12: 0
